Workbook

Sheet Legend
A1: 2026 Draft Cheat Sheet — Three-Source Consensus
A2: Blends Hayden Winks and Josh Norris (Yahoo Sports, Aug 12 2026) with the FantasyPros Expert Consensus Ranking (Aug 25 2026, 111 experts half-PPR / 108 PPR).
A3: Half PPR and Full PPR are separate boards. FantasyPros is capped at its top 300; anyone it ranks below that is treated as omitted.
A5: WHICH CELLS YOU EDIT
A6: Two columns are yours: Drafted and Notes. The weights and penalties below are also editable. Everything else recalculates — but the rows will not resort themselves, so use the header filters to sort by Avg after changing a weight.
A7: Drafted | B7: Pick ME or TAKEN from the dropdown. Rows turn green or grey out.
A8: Notes | B8: Your own reads — injury notes, 'do not draft', target round.
A10: EXAMPLE OF A FILLED ROW
A11: Rank | B11: Tier | C11: PosTier | D11: Player | E11: Pos | F11: PosRank | G11: Team | H11: Avg | I11: Winks | J11: Norris | K11: FantasyPros | L11: Range | M11: Drafted | N11: Notes
A12: 19 | B12: 7 | C12: 4 | D12: Omarion Hampton | E12: RB | F12: 9 | G12: LAC | H12: 19 | I12: 24 | J12: 15 | K12: 19 | L12: 9 | M12: ME | N12: volume is there, line is shaky
A14: COLUMN MEANINGS
A15: Tier | B15: Overall tier. A break means a real drop-off in consensus value.
A16: PosTier | B16: Tier within the position — the one to use mid-draft. It tells you how many comparable players remain at that spot.
A17: Avg | B17: Weighted average of the three sources. Formula — driven by the weights and penalties below.
A18: Winks / Norris / FantasyPros | B18: Each source's own rank. Blank means that source left the player off (or ranked them past FantasyPros' top 300).
A19: Range | B19: Highest minus lowest rank across the sources. A big number means they genuinely disagree and the pick is a judgment call.
A21: WEIGHTS
A22: FantasyPros ECR is itself an average of 100+ experts, so weighting it equal to one analyst would understate the market. It is set to double. Change these to shift the blend — set FantasyPros to 1 to treat all three as equal opinions.
A23: Winks weight | B23: 1
A24: Norris weight | B24: 1
A25: FantasyPros weight | B25: 2
A27: OMISSION PENALTIES
A28: When a source leaves a player off entirely, that counts as a rank just past the end of their list rather than being ignored — being omitted from a board is information. These update from the actual list sizes on every rebuild.
A29: Half PPR — Winks | B29: 315 | C29: list is 300 deep
A30: Half PPR — Norris | B30: 321 | C30: list is 306 deep
A31: Half PPR — FantasyPros | B31: 315 | C31: list is 300 deep
A32: Full PPR — Winks | B32: 316 | C32: list is 301 deep
A33: Full PPR — Norris | B33: 317 | C33: list is 302 deep
A34: Full PPR — FantasyPros | B34: 315 | C34: list is 300 deep
A36: Blue on yellow are hard-coded inputs you can change. Black is a formula.
A37: Your no-kicker league: the extra flex makes RB/WR depth matter more than the K column. Filter by Pos and work past RB60 / WR72.

Sheet Half PPR
A1: Half PPR — Winks + Norris + FantasyPros consensus
A2: Filter with the header arrows. Set Drafted to dim a row. A shaded Range means the sources disagree by 40 or more.
A4: Rank | B4: Tier | C4: PosTier | D4: Player | E4: Pos | F4: PosRank | G4: Team | H4: Avg | I4: Winks | J4: Norris | K4: FantasyPros | L4: Range | M4: Drafted | N4: Notes
A5: 1 | B5: 1 | C5: 1 | D5: Jahmyr Gibbs | E5: RB | F5: 1 | G5: DET | H5: =(IF(I5="",Legend!$B$29,I5)*Legend!$B$23+IF(J5="",Legend!$B$30,J5)*Legend!$B$24+IF(K5="",Legend!$B$31,K5)*Legend!$B$25)/(Legend!$B$23+Legend!$B$24+Legend!$B$25) | I5: 1 | J5: 1 | K5: 1 | L5: =IF(COUNT(I5:K5)<2,"",MAX(I5:K5)-MIN(I5:K5))
A6: 2 | B6: 1 | C6: 1 | D6: Bijan Robinson | E6: RB | F6: 2 | G6: ATL | H6: =(IF(I6="",Legend!$B$29,I6)*Legend!$B$23+IF(J6="",Legend!$B$30,J6)*Legend!$B$24+IF(K6="",Legend!$B$31,K6)*Legend!$B$25)/(Legend!$B$23+Legend!$B$24+Legend!$B$25) | I6: 2 | J6: 2 | K6: 2 | L6: =IF(COUNT(I6:K6)<2,"",MAX(I6:K6)-MIN(I6:K6))
A7: 3 | B7: 1 | C7: 1 | D7: Ja'Marr Chase | E7: WR | F7: 1 | G7: CIN | H7: =(IF(I7="",Legend!$B$29,I7)*Legend!$B$23+IF(J7="",Legend!$B$30,J7)*Legend!$B$24+IF(K7="",Legend!$B$31,K7)*Legend!$B$25)/(Legend!$B$23+Legend!$B$24+Legend!$B$25) | I7: 3 | J7: 3 | K7: 3 | L7: =IF(COUNT(I7:K7)<2,"",MAX(I7:K7)-MIN(I7:K7))
A8: 4 | B8: 1 | C8: 1 | D8: Puka Nacua | E8: WR | F8: 2 | G8: LAR | H8: =(IF(I8="",Legend!$B$29,I8)*Legend!$B$23+IF(J8="",Legend!$B$30,J8)*Legend!$B$24+IF(K8="",Legend!$B$31,K8)*Legend!$B$25)/(Legend!$B$23+Legend!$B$24+Legend!$B$25) | I8: 4 | J8: 4 | K8: 4 | L8: =IF(COUNT(I8:K8)<2,"",MAX(I8:K8)-MIN(I8:K8))
A9: 5 | B9: 2 | C9: 1 | D9: Amon-Ra St. Brown | E9: WR | F9: 3 | G9: DET | H9: =(IF(I9="",Legend!$B$29,I9)*Legend!$B$23+IF(J9="",Legend!$B$30,J9)*Legend!$B$24+IF(K9="",Legend!$B$31,K9)*Legend!$B$25)/(Legend!$B$23+Legend!$B$24+Legend!$B$25) | I9: 7 | J9: 5 | K9: 6 | L9: =IF(COUNT(I9:K9)<2,"",MAX(I9:K9)-MIN(I9:K9))
A10: 6 | B10: 2 | C10: 1 | D10: Jaxon Smith-Njigba | E10: WR | F10: 4 | G10: SEA | H10: =(IF(I10="",Legend!$B$29,I10)*Legend!$B$23+IF(J10="",Legend!$B$30,J10)*Legend!$B$24+IF(K10="",Legend!$B$31,K10)*Legend!$B$25)/(Legend!$B$23+Legend!$B$24+Legend!$B$25) | I10: 8 | J10: 8 | K10: 5 | L10: =IF(COUNT(I10:K10)<2,"",MAX(I10:K10)-MIN(I10:K10))
A11: 7 | B11: 2 | C11: 2 | D11: Jonathan Taylor | E11: RB | F11: 3 | G11: IND | H11: =(IF(I11="",Legend!$B$29,I11)*Legend!$B$23+IF(J11="",Legend!$B$30,J11)*Legend!$B$24+IF(K11="",Legend!$B$31,K11)*Legend!$B$25)/(Legend!$B$23+Legend!$B$24+Legend!$B$25) | I11: 6 | J11: 6 | K11: 7 | L11: =IF(COUNT(I11:K11)<2,"",MAX(I11:K11)-MIN(I11:K11))
A12: 8 | B12: 2 | C12: 2 | D12: Christian McCaffrey | E12: RB | F12: 4 | G12: SF | H12: =(IF(I12="",Legend!$B$29,I12)*Legend!$B$23+IF(J12="",Legend!$B$30,J12)*Legend!$B$24+IF(K12="",Legend!$B$31,K12)*Legend!$B$25)/(Legend!$B$23+Legend!$B$24+Legend!$B$25) | I12: 5 | J12: 7 | K12: 8 | L12: =IF(COUNT(I12:K12)<2,"",MAX(I12:K12)-MIN(I12:K12))
A13: 9 | B13: 3 | C13: 2 | D13: CeeDee Lamb | E13: WR | F13: 5 | G13: DAL | H13: =(IF(I13="",Legend!$B$29,I13)*Legend!$B$23+IF(J13="",Legend!$B$30,J13)*Legend!$B$24+IF(K13="",Legend!$B$31,K13)*Legend!$B$25)/(Legend!$B$23+Legend!$B$24+Legend!$B$25) | I13: 10 | J13: 11 | K13: 9 | L13: =IF(COUNT(I13:K13)<2,"",MAX(I13:K13)-MIN(I13:K13))
A14: 10 | B14: 4 | C14: 3 | D14: James Cook III | E14: RB | F14: 5 | G14: BUF | H14: =(IF(I14="",Legend!$B$29,I14)*Legend!$B$23+IF(J14="",Legend!$B$30,J14)*Legend!$B$24+IF(K14="",Legend!$B$31,K14)*Legend!$B$25)/(Legend!$B$23+Legend!$B$24+Legend!$B$25) | I14: 13 | J14: 12 | K14: 10 | L14: =IF(COUNT(I14:K14)<2,"",MAX(I14:K14)-MIN(I14:K14))
A15: 11 | B15: 4 | C15: 2 | D15: Justin Jefferson | E15: WR | F15: 6 | G15: MIN | H15: =(IF(I15="",Legend!$B$29,I15)*Legend!$B$23+IF(J15="",Legend!$B$30,J15)*Legend!$B$24+IF(K15="",Legend!$B$31,K15)*Legend!$B$25)/(Legend!$B$23+Legend!$B$24+Legend!$B$25) | I15: 16 | J15: 10 | K15: 11 | L15: =IF(COUNT(I15:K15)<2,"",MAX(I15:K15)-MIN(I15:K15))
A16: 12 | B16: 4 | C16: 3 | D16: Saquon Barkley | E16: RB | F16: 6 | G16: PHI | H16: =(IF(I16="",Legend!$B$29,I16)*Legend!$B$23+IF(J16="",Legend!$B$30,J16)*Legend!$B$24+IF(K16="",Legend!$B$31,K16)*Legend!$B$25)/(Legend!$B$23+Legend!$B$24+Legend!$B$25) | I16: 12 | J16: 9 | K16: 15 | L16: =IF(COUNT(I16:K16)<2,"",MAX(I16:K16)-MIN(I16:K16))
... A258: 254 | B258: 48 | C258: 16 | D258: Kirk Cousins | E258: QB | F258: 32 | G258: LV | H258: =(IF(I258="",Legend!$B$29,I258)*Legend!$B$23+IF(J258="",Legend!$B$30,J258)*Legend!$B$24+IF(K258="",Legend!$B$31,K258)*Legend!$B$25)/(Legend!$B$23+Legend!$B$24+Legend!$B$25) | I258: 260 | J258: 206 | K258: 269 | L258: =IF(COUNT(I258:K258)<2,"",MAX(I258:K258)-MIN(I258:K258))
A259: 255 | B259: 48 | C259: 24 | D259: Troy Franklin | E259: WR | F259: 91 | G259: DEN | H259: =(IF(I259="",Legend!$B$29,I259)*Legend!$B$23+IF(J259="",Legend!$B$30,J259)*Legend!$B$24+IF(K259="",Legend!$B$31,K259)*Legend!$B$25)/(Legend!$B$23+Legend!$B$24+Legend!$B$25) | J259: 258 | K259: 217 | L259: =IF(COUNT(I259:K259)<2,"",MAX(I259:K259)-MIN(I259:K259))
A260: 256 | B260: 48 | C260: 22 | D260: Isaiah Davis | E260: RB | F260: 71 | G260: NYJ | H260: =(IF(I260="",Legend!$B$29,I260)*Legend!$B$23+IF(J260="",Legend!$B$30,J260)*Legend!$B$24+IF(K260="",Legend!$B$31,K260)*Legend!$B$25)/(Legend!$B$23+Legend!$B$24+Legend!$B$25) | I260: 288 | J260: 228 | K260: 246 | L260: =IF(COUNT(I260:K260)<2,"",MAX(I260:K260)-MIN(I260:K260))
A261: 257 | B261: 48 | C261: 22 | D261: Jaylen Wright | E261: RB | F261: 72 | G261: MIA | H261: =(IF(I261="",Legend!$B$29,I261)*Legend!$B$23+IF(J261="",Legend!$B$30,J261)*Legend!$B$24+IF(K261="",Legend!$B$31,K261)*Legend!$B$25)/(Legend!$B$23+Legend!$B$24+Legend!$B$25) | J261: 240 | K261: 227 | L261: =IF(COUNT(I261:K261)<2,"",MAX(I261:K261)-MIN(I261:K261))
A262: 258 | B262: 48 | C262: 22 | D262: Justice Hill | E262: RB | F262: 73 | G262: BAL | H262: =(IF(I262="",Legend!$B$29,I262)*Legend!$B$23+IF(J262="",Legend!$B$30,J262)*Legend!$B$24+IF(K262="",Legend!$B$31,K262)*Legend!$B$25)/(Legend!$B$23+Legend!$B$24+Legend!$B$25) | I262: 272 | J262: 254 | K262: 243 | L262: =IF(COUNT(I262:K262)<2,"",MAX(I262:K262)-MIN(I262:K262))
A263: 259 | B263: 48 | C263: 4 | D263: Cleveland Browns | E263: DST | F263: 16 | G263: CLE | H263: =(IF(I263="",Legend!$B$29,I263)*Legend!$B$23+IF(J263="",Legend!$B$30,J263)*Legend!$B$24+IF(K263="",Legend!$B$31,K263)*Legend!$B$25)/(Legend!$B$23+Legend!$B$24+Legend!$B$25) | I263: 245 | J263: 253 | K263: 259 | L263: =IF(COUNT(I263:K263)<2,"",MAX(I263:K263)-MIN(I263:K263))
A264: 260 | B264: 49 | C264: 24 | D264: Antonio Williams | E264: WR | F264: 92 | G264: WAS | H264: =(IF(I264="",Legend!$B$29,I264)*Legend!$B$23+IF(J264="",Legend!$B$30,J264)*Legend!$B$24+IF(K264="",Legend!$B$31,K264)*Legend!$B$25)/(Legend!$B$23+Legend!$B$24+Legend!$B$25) | I264: 286 | J264: 251 | K264: 242 | L264: =IF(COUNT(I264:K264)<2,"",MAX(I264:K264)-MIN(I264:K264))
A265: 261 | B265: 49 | C265: 24 | D265: Ted Hurst III | E265: WR | F265: 93 | G265: TB | H265: =(IF(I265="",Legend!$B$29,I265)*Legend!$B$23+IF(J265="",Legend!$B$30,J265)*Legend!$B$24+IF(K265="",Legend!$B$31,K265)*Legend!$B$25)/(Legend!$B$23+Legend!$B$24+Legend!$B$25) | I265: 275 | J265: 229 | K265: 260 | L265: =IF(COUNT(I265:K265)<2,"",MAX(I265:K265)-MIN(I265:K265))
A266: 262 | B266: 50 | C266: 4 | D266: Chris Boswell | E266: K | F266: 16 | G266: PIT | H266: =(IF(I266="",Legend!$B$29,I266)*Legend!$B$23+IF(J266="",Legend!$B$30,J266)*Legend!$B$24+IF(K266="",Legend!$B$31,K266)*Legend!$B$25)/(Legend!$B$23+Legend!$B$24+Legend!$B$25) | I266: 243 | J266: 264 | K266: 265 | L266: =IF(COUNT(I266:K266)<2,"",MAX(I266:K266)-MIN(I266:K266))
A267: 263 | B267: 50 | C267: 23 | D267: Samaje Perine | E267: RB | F267: 74 | G267: CIN | H267: =(IF(I267="",Legend!$B$29,I267)*Legend!$B$23+IF(J267="",Legend!$B$30,J267)*Legend!$B$24+IF(K267="",Legend!$B$31,K267)*Legend!$B$25)/(Legend!$B$23+Legend!$B$24+Legend!$B$25) | I267: 232 | J267: 284 | K267: 261 | L267: =IF(COUNT(I267:K267)<2,"",MAX(I267:K267)-MIN(I267:K267))
A268: 264 | B268: 50 | C268: 24 | D268: Tyquan Thornton | E268: WR | F268: 94 | G268: KC | H268: =(IF(I268="",Legend!$B$29,I268)*Legend!$B$23+IF(J268="",Legend!$B$30,J268)*Legend!$B$24+IF(K268="",Legend!$B$31,K268)*Legend!$B$25)/(Legend!$B$23+Legend!$B$24+Legend!$B$25) | I268: 269 | J268: 230 | K268: 270 | L268: =IF(COUNT(I268:K268)<2,"",MAX(I268:K268)-MIN(I268:K268))
A269: 265 | B269: 51 | C269: 24 | D269: Chris Brooks | E269: RB | F269: 75 | G269: GB | H269: =(IF(I269="",Legend!$B$29,I269)*Legend!$B$23+IF(J269="",Legend!$B$30,J269)*Legend!$B$24+IF(K269="",Legend!$B$31,K269)*Legend!$B$25)/(Legend!$B$23+Legend!$B$24+Legend!$B$25) | I269: 290 | J269: 259 | K269: 253 | L269: =IF(COUNT(I269:K269)<2,"",MAX(I269:K269)-MIN(I269:K269))
A270: 266 | B270: 51 | C270: 4 | D270: San Francisco 49ers | E270: DST | F270: 17 | G270: SF | H270: =(IF(I270="",Legend!$B$29,I270)*Legend!$B$23+IF(J270="",Legend!$B$30,J270)*Legend!$B$24+IF(K270="",Legend!$B$31,K270)*Legend!$B$25)/(Legend!$B$23+Legend!$B$24+Legend!$B$25) | I270: 228 | J270: 244 | K270: 292 | L270: =IF(COUNT(I270:K270)<2,"",MAX(I270:K270)-MIN(I270:K270))
A271: 267 | B271: 52 | C271: 24 | D271: Jordan James | E271: RB | F271: 76 | G271: SF | H271: =(IF(I271="",Legend!$B$29,I271)*Legend!$B$23+IF(J271="",Legend!$B$30,J271)*Legend!$B$24+IF(K271="",Legend!$B$31,K271)*Legend!$B$25)/(Legend!$B$23+Legend!$B$24+Legend!$B$25) | I271: 280 | J271: 272 | K271: 258 | L271: =IF(COUNT(I271:K271)<2,"",MAX(I271:K271)-MIN(I271:K271))
A272: 268 | B272: 52 | C272: 25 | D272: Darius Slayton | E272: WR | F272: 95 | G272: NYG | H272: =(IF(I272="",Legend!$B$29,I272)*Legend!$B$23+IF(J272="",Legend!$B$30,J272)*Legend!$B$24+IF(K272="",Legend!$B$31,K272)*Legend!$B$25)/(Legend!$B$23+Legend!$B$24+Legend!$B$25) | I272: 237 | J272: 289 | K272: 272 | L272: =IF(COUNT(I272:K272)<2,"",MAX(I272:K272)-MIN(I272:K272))
A273: 269 | B273: 52 | C273: 4 | D273: Harrison Butker | E273: K | F273: 17 | G273: KC | H273: =(IF(I273="",Legend!$B$29,I273)*Legend!$B$23+IF(J273="",Legend!$B$30,J273)*Legend!$B$24+IF(K273="",Legend!$B$31,K273)*Legend!$B$25)/(Legend!$B$23+Legend!$B$24+Legend!$B$25) | I273: 296 | J273: 265 | K273: 256 | L273: =IF(COUNT(I273:K273)<2,"",MAX(I273:K273)-MIN(I273:K273))
... A277: 273 | B277: 52 | C277: 25 | D277: Xavier Legette | E277: WR | F277: 98 | G277: CAR | H277: =(IF(I277="",Legend!$B$29,I277)*Legend!$B$23+IF(J277="",Legend!$B$30,J277)*Legend!$B$24+IF(K277="",Legend!$B$31,K277)*Legend!$B$25)/(Legend!$B$23+Legend!$B$24+Legend!$B$25) | I277: 300 | J277: 220 | K277: 280 | L277: =IF(COUNT(I277:K277)<2,"",MAX(I277:K277)-MIN(I277:K277))
A278: 274 | B278: 53 | C278: 25 | D278: Treylon Burks | E278: WR | F278: 99 | G278: WAS | H278: =(IF(I278="",Legend!$B$29,I278)*Legend!$B$23+IF(J278="",Legend!$B$30,J278)*Legend!$B$24+IF(K278="",Legend!$B$31,K278)*Legend!$B$25)/(Legend!$B$23+Legend!$B$24+Legend!$B$25) | I278: 223 | J278: 236 | L278: =IF(COUNT(I278:K278)<2,"",MAX(I278:K278)-MIN(I278:K278))
A279: 275 | B279: 53 | C279: 24 | D279: Demond Claiborne | E279: RB | F279: 78 | G279: MIN | H279: =(IF(I279="",Legend!$B$29,I279)*Legend!$B$23+IF(J279="",Legend!$B$30,J279)*Legend!$B$24+IF(K279="",Legend!$B$31,K279)*Legend!$B$25)/(Legend!$B$23+Legend!$B$24+Legend!$B$25) | J279: 279 | K279: 248 | L279: =IF(COUNT(I279:K279)<2,"",MAX(I279:K279)-MIN(I279:K279))
A280: 276 | B280: 53 | C280: 17 | D280: Michael Penix Jr. | E280: QB | F280: 33 | G280: ATL | H280: =(IF(I280="",Legend!$B$29,I280)*Legend!$B$23+IF(J280="",Legend!$B$30,J280)*Legend!$B$24+IF(K280="",Legend!$B$31,K280)*Legend!$B$25)/(Legend!$B$23+Legend!$B$24+Legend!$B$25) | I280: 261 | J280: 298 | K280: 266 | L280: =IF(COUNT(I280:K280)<2,"",MAX(I280:K280)-MIN(I280:K280))
A281: 277 | B281: 53 | C281: 25 | D281: Elijah Sarratt | E281: WR | F281: 100 | G281: BAL | H281: =(IF(I281="",Legend!$B$29,I281)*Legend!$B$23+IF(J281="",Legend!$B$30,J281)*Legend!$B$24+IF(K281="",Legend!$B$31,K281)*Legend!$B$25)/(Legend!$B$23+Legend!$B$24+Legend!$B$25) | I281: 287 | J281: 252 | K281: 278 | L281: =IF(COUNT(I281:K281)<2,"",MAX(I281:K281)-MIN(I281:K281))
A282: 278 | B282: 53 | C282: 16 | D282: Mason Taylor | E282: TE | F282: 33 | G282: NYJ | H282: =(IF(I282="",Legend!$B$29,I282)*Legend!$B$23+IF(J282="",Legend!$B$30,J282)*Legend!$B$24+IF(K282="",Legend!$B$31,K282)*Legend!$B$25)/(Legend!$B$23+Legend!$B$24+Legend!$B$25) | I282: 263 | J282: 285 | K282: 276 | L282: =IF(COUNT(I282:K282)<2,"",MAX(I282:K282)-MIN(I282:K282))
A283: 279 | B283: 53 | C283: 24 | D283: LeQuint Allen Jr. | E283: RB | F283: 79 | G283: JAC | H283: =(IF(I283="",Legend!$B$29,I283)*Legend!$B$23+IF(J283="",Legend!$B$30,J283)*Legend!$B$24+IF(K283="",Legend!$B$31,K283)*Legend!$B$25)/(Legend!$B$23+Legend!$B$24+Legend!$B$25) | I283: 284 | J283: 288 | K283: 267 | L283: =IF(COUNT(I283:K283)<2,"",MAX(I283:K283)-MIN(I283:K283))
A284: 280 | B284: 53 | C284: 24 | D284: Seth McGowan | E284: RB | F284: 80 | G284: IND | H284: =(IF(I284="",Legend!$B$29,I284)*Legend!$B$23+IF(J284="",Legend!$B$30,J284)*Legend!$B$24+IF(K284="",Legend!$B$31,K284)*Legend!$B$25)/(Legend!$B$23+Legend!$B$24+Legend!$B$25) | I284: 241 | J284: 301 | K284: 283 | L284: =IF(COUNT(I284:K284)<2,"",MAX(I284:K284)-MIN(I284:K284))
A285: 281 | B285: 53 | C285: 24 | D285: Ty Johnson | E285: RB | F285: 81 | G285: BUF | H285: =(IF(I285="",Legend!$B$29,I285)*Legend!$B$23+IF(J285="",Legend!$B$30,J285)*Legend!$B$24+IF(K285="",Legend!$B$31,K285)*Legend!$B$25)/(Legend!$B$23+Legend!$B$24+Legend!$B$25) | J285: 269 | K285: 262 | L285: =IF(COUNT(I285:K285)<2,"",MAX(I285:K285)-MIN(I285:K285))
...

Sheet Full PPR
A1: Full PPR — Winks + Norris + FantasyPros consensus
A2: Filter with the header arrows. Set Drafted to dim a row. A shaded Range means the sources disagree by 40 or more.
A4: Rank | B4: Tier | C4: PosTier | D4: Player | E4: Pos | F4: PosRank | G4: Team | H4: Avg | I4: Winks | J4: Norris | K4: FantasyPros | L4: Range | M4: Drafted | N4: Notes
A5: 1 | B5: 1 | C5: 1 | D5: Jahmyr Gibbs | E5: RB | F5: 1 | G5: DET | H5: =(IF(I5="",Legend!$B$32,I5)*Legend!$B$23+IF(J5="",Legend!$B$33,J5)*Legend!$B$24+IF(K5="",Legend!$B$34,K5)*Legend!$B$25)/(Legend!$B$23+Legend!$B$24+Legend!$B$25) | I5: 1 | J5: 1 | K5: 2 | L5: =IF(COUNT(I5:K5)<2,"",MAX(I5:K5)-MIN(I5:K5))
A6: 2 | B6: 1 | C6: 1 | D6: Ja'Marr Chase | E6: WR | F6: 1 | G6: CIN | H6: =(IF(I6="",Legend!$B$32,I6)*Legend!$B$23+IF(J6="",Legend!$B$33,J6)*Legend!$B$24+IF(K6="",Legend!$B$34,K6)*Legend!$B$25)/(Legend!$B$23+Legend!$B$24+Legend!$B$25) | I6: 2 | J6: 3 | K6: 1 | L6: =IF(COUNT(I6:K6)<2,"",MAX(I6:K6)-MIN(I6:K6))
A7: 3 | B7: 2 | C7: 1 | D7: Puka Nacua | E7: WR | F7: 2 | G7: LAR | H7: =(IF(I7="",Legend!$B$32,I7)*Legend!$B$23+IF(J7="",Legend!$B$33,J7)*Legend!$B$24+IF(K7="",Legend!$B$34,K7)*Legend!$B$25)/(Legend!$B$23+Legend!$B$24+Legend!$B$25) | I7: 3 | J7: 4 | K7: 3 | L7: =IF(COUNT(I7:K7)<2,"",MAX(I7:K7)-MIN(I7:K7))
A8: 4 | B8: 2 | C8: 1 | D8: Bijan Robinson | E8: RB | F8: 2 | G8: ATL | H8: =(IF(I8="",Legend!$B$32,I8)*Legend!$B$23+IF(J8="",Legend!$B$33,J8)*Legend!$B$24+IF(K8="",Legend!$B$34,K8)*Legend!$B$25)/(Legend!$B$23+Legend!$B$24+Legend!$B$25) | I8: 4 | J8: 2 | K8: 4 | L8: =IF(COUNT(I8:K8)<2,"",MAX(I8:K8)-MIN(I8:K8))
A9: 5 | B9: 3 | C9: 1 | D9: Amon-Ra St. Brown | E9: WR | F9: 3 | G9: DET | H9: =(IF(I9="",Legend!$B$32,I9)*Legend!$B$23+IF(J9="",Legend!$B$33,J9)*Legend!$B$24+IF(K9="",Legend!$B$34,K9)*Legend!$B$25)/(Legend!$B$23+Legend!$B$24+Legend!$B$25) | I9: 5 | J9: 5 | K9: 6 | L9: =IF(COUNT(I9:K9)<2,"",MAX(I9:K9)-MIN(I9:K9))
A10: 6 | B10: 3 | C10: 1 | D10: Jaxon Smith-Njigba | E10: WR | F10: 4 | G10: SEA | H10: =(IF(I10="",Legend!$B$32,I10)*Legend!$B$23+IF(J10="",Legend!$B$33,J10)*Legend!$B$24+IF(K10="",Legend!$B$34,K10)*Legend!$B$25)/(Legend!$B$23+Legend!$B$24+Legend!$B$25) | I10: 6 | J10: 6 | K10: 5 | L10: =IF(COUNT(I10:K10)<2,"",MAX(I10:K10)-MIN(I10:K10))
A11: 7 | B11: 4 | C11: 1 | D11: CeeDee Lamb | E11: WR | F11: 5 | G11: DAL | H11: =(IF(I11="",Legend!$B$32,I11)*Legend!$B$23+IF(J11="",Legend!$B$33,J11)*Legend!$B$24+IF(K11="",Legend!$B$34,K11)*Legend!$B$25)/(Legend!$B$23+Legend!$B$24+Legend!$B$25) | I11: 8 | J11: 9 | K11: 7 | L11: =IF(COUNT(I11:K11)<2,"",MAX(I11:K11)-MIN(I11:K11))
A12: 8 | B12: 4 | C12: 2 | D12: Christian McCaffrey | E12: RB | F12: 3 | G12: SF | H12: =(IF(I12="",Legend!$B$32,I12)*Legend!$B$23+IF(J12="",Legend!$B$33,J12)*Legend!$B$24+IF(K12="",Legend!$B$34,K12)*Legend!$B$25)/(Legend!$B$23+Legend!$B$24+Legend!$B$25) | I12: 7 | J12: 10 | K12: 9 | L12: =IF(COUNT(I12:K12)<2,"",MAX(I12:K12)-MIN(I12:K12))
A13: 9 | B13: 4 | C13: 2 | D13: Jonathan Taylor | E13: RB | F13: 4 | G13: IND | H13: =(IF(I13="",Legend!$B$32,I13)*Legend!$B$23+IF(J13="",Legend!$B$33,J13)*Legend!$B$24+IF(K13="",Legend!$B$34,K13)*Legend!$B$25)/(Legend!$B$23+Legend!$B$24+Legend!$B$25) | I13: 9 | J13: 7 | K13: 10 | L13: =IF(COUNT(I13:K13)<2,"",MAX(I13:K13)-MIN(I13:K13))
A14: 10 | B14: 4 | C14: 1 | D14: Justin Jefferson | E14: WR | F14: 6 | G14: MIN | H14: =(IF(I14="",Legend!$B$32,I14)*Legend!$B$23+IF(J14="",Legend!$B$33,J14)*Legend!$B$24+IF(K14="",Legend!$B$34,K14)*Legend!$B$25)/(Legend!$B$23+Legend!$B$24+Legend!$B$25) | I14: 12 | J14: 8 | K14: 8 | L14: =IF(COUNT(I14:K14)<2,"",MAX(I14:K14)-MIN(I14:K14))
A15: 11 | B15: 5 | C15: 3 | D15: James Cook III | E15: RB | F15: 5 | G15: BUF | H15: =(IF(I15="",Legend!$B$32,I15)*Legend!$B$23+IF(J15="",Legend!$B$33,J15)*Legend!$B$24+IF(K15="",Legend!$B$34,K15)*Legend!$B$25)/(Legend!$B$23+Legend!$B$24+Legend!$B$25) | I15: 15 | J15: 13 | K15: 14 | L15: =IF(COUNT(I15:K15)<2,"",MAX(I15:K15)-MIN(I15:K15))
A16: 12 | B16: 5 | C16: 2 | D16: Nico Collins | E16: WR | F16: 7 | G16: HOU | H16: =(IF(I16="",Legend!$B$32,I16)*Legend!$B$23+IF(J16="",Legend!$B$33,J16)*Legend!$B$24+IF(K16="",Legend!$B$34,K16)*Legend!$B$25)/(Legend!$B$23+Legend!$B$24+Legend!$B$25) | I16: 13 | J16: 17 | K16: 13 | L16: =IF(COUNT(I16:K16)<2,"",MAX(I16:K16)-MIN(I16:K16))
... A242: 238 | B242: 45 | C242: 23 | D242: Cyrus Allen | E242: WR | F242: 83 | G242: KC | H242: =(IF(I242="",Legend!$B$32,I242)*Legend!$B$23+IF(J242="",Legend!$B$33,J242)*Legend!$B$24+IF(K242="",Legend!$B$34,K242)*Legend!$B$25)/(Legend!$B$23+Legend!$B$24+Legend!$B$25) | I242: 221 | J242: 165 | K242: 284 | L242: =IF(COUNT(I242:K242)<2,"",MAX(I242:K242)-MIN(I242:K242))
A243: 239 | B243: 45 | C243: 19 | D243: Nicholas Singleton | E243: RB | F243: 66 | G243: TEN | H243: =(IF(I243="",Legend!$B$32,I243)*Legend!$B$23+IF(J243="",Legend!$B$33,J243)*Legend!$B$24+IF(K243="",Legend!$B$34,K243)*Legend!$B$25)/(Legend!$B$23+Legend!$B$24+Legend!$B$25) | J243: 232 | K243: 204 | L243: =IF(COUNT(I243:K243)<2,"",MAX(I243:K243)-MIN(I243:K243))
A244: 240 | B244: 45 | C244: 23 | D244: Isaac TeSlaa | E244: WR | F244: 84 | G244: DET | H244: =(IF(I244="",Legend!$B$32,I244)*Legend!$B$23+IF(J244="",Legend!$B$33,J244)*Legend!$B$24+IF(K244="",Legend!$B$34,K244)*Legend!$B$25)/(Legend!$B$23+Legend!$B$24+Legend!$B$25) | I244: 284 | J244: 245 | K244: 215 | L244: =IF(COUNT(I244:K244)<2,"",MAX(I244:K244)-MIN(I244:K244))
A245: 241 | B245: 46 | C245: 15 | D245: Evan Engram | E245: TE | F245: 30 | G245: DEN | H245: =(IF(I245="",Legend!$B$32,I245)*Legend!$B$23+IF(J245="",Legend!$B$33,J245)*Legend!$B$24+IF(K245="",Legend!$B$34,K245)*Legend!$B$25)/(Legend!$B$23+Legend!$B$24+Legend!$B$25) | I245: 236 | J245: 259 | K245: 239 | L245: =IF(COUNT(I245:K245)<2,"",MAX(I245:K245)-MIN(I245:K245))
A246: 242 | B246: 46 | C246: 24 | D246: Germie Bernard | E246: WR | F246: 85 | G246: PIT | H246: =(IF(I246="",Legend!$B$32,I246)*Legend!$B$23+IF(J246="",Legend!$B$33,J246)*Legend!$B$24+IF(K246="",Legend!$B$34,K246)*Legend!$B$25)/(Legend!$B$23+Legend!$B$24+Legend!$B$25) | I246: 246 | J246: 267 | K246: 230 | L246: =IF(COUNT(I246:K246)<2,"",MAX(I246:K246)-MIN(I246:K246))
A247: 243 | B247: 46 | C247: 19 | D247: Emanuel Wilson | E247: RB | F247: 67 | G247: SEA | H247: =(IF(I247="",Legend!$B$32,I247)*Legend!$B$23+IF(J247="",Legend!$B$33,J247)*Legend!$B$24+IF(K247="",Legend!$B$34,K247)*Legend!$B$25)/(Legend!$B$23+Legend!$B$24+Legend!$B$25) | I247: 296 | J247: 233 | K247: 223 | L247: =IF(COUNT(I247:K247)<2,"",MAX(I247:K247)-MIN(I247:K247))
A248: 244 | B248: 46 | C248: 24 | D248: Zachariah Branch | E248: WR | F248: 86 | G248: ATL | H248: =(IF(I248="",Legend!$B$32,I248)*Legend!$B$23+IF(J248="",Legend!$B$33,J248)*Legend!$B$24+IF(K248="",Legend!$B$34,K248)*Legend!$B$25)/(Legend!$B$23+Legend!$B$24+Legend!$B$25) | I248: 283 | J248: 231 | K248: 234 | L248: =IF(COUNT(I248:K248)<2,"",MAX(I248:K248)-MIN(I248:K248))
A249: 245 | B249: 46 | C249: 19 | D249: Jaydon Blue | E249: RB | F249: 68 | G249: DAL | H249: =(IF(I249="",Legend!$B$32,I249)*Legend!$B$23+IF(J249="",Legend!$B$33,J249)*Legend!$B$24+IF(K249="",Legend!$B$34,K249)*Legend!$B$25)/(Legend!$B$23+Legend!$B$24+Legend!$B$25) | I249: 249 | J249: 294 | K249: 222 | L249: =IF(COUNT(I249:K249)<2,"",MAX(I249:K249)-MIN(I249:K249))
A250: 246 | B250: 46 | C250: 15 | D250: Colby Parkinson | E250: TE | F250: 31 | G250: LAR | H250: =(IF(I250="",Legend!$B$32,I250)*Legend!$B$23+IF(J250="",Legend!$B$33,J250)*Legend!$B$24+IF(K250="",Legend!$B$34,K250)*Legend!$B$25)/(Legend!$B$23+Legend!$B$24+Legend!$B$25) | I250: 214 | J250: 257 | K250: 260 | L250: =IF(COUNT(I250:K250)<2,"",MAX(I250:K250)-MIN(I250:K250))
A251: 247 | B251: 46 | C251: 24 | D251: Cooper Kupp | E251: WR | F251: 87 | G251: SEA | H251: =(IF(I251="",Legend!$B$32,I251)*Legend!$B$23+IF(J251="",Legend!$B$33,J251)*Legend!$B$24+IF(K251="",Legend!$B$34,K251)*Legend!$B$25)/(Legend!$B$23+Legend!$B$24+Legend!$B$25) | I251: 287 | J251: 263 | K251: 221 | L251: =IF(COUNT(I251:K251)<2,"",MAX(I251:K251)-MIN(I251:K251))
A252: 248 | B252: 46 | C252: 24 | D252: Jack Bech | E252: WR | F252: 88 | G252: LV | H252: =(IF(I252="",Legend!$B$32,I252)*Legend!$B$23+IF(J252="",Legend!$B$33,J252)*Legend!$B$24+IF(K252="",Legend!$B$34,K252)*Legend!$B$25)/(Legend!$B$23+Legend!$B$24+Legend!$B$25) | I252: 295 | J252: 223 | K252: 238 | L252: =IF(COUNT(I252:K252)<2,"",MAX(I252:K252)-MIN(I252:K252))
A253: 249 | B253: 46 | C253: 24 | D253: Keon Coleman | E253: WR | F253: 89 | G253: BUF | H253: =(IF(I253="",Legend!$B$32,I253)*Legend!$B$23+IF(J253="",Legend!$B$33,J253)*Legend!$B$24+IF(K253="",Legend!$B$34,K253)*Legend!$B$25)/(Legend!$B$23+Legend!$B$24+Legend!$B$25) | I253: 224 | J253: 275 | K253: 249 | L253: =IF(COUNT(I253:K253)<2,"",MAX(I253:K253)-MIN(I253:K253))
A254: 250 | B254: 46 | C254: 5 | D254: Wil Lutz | E254: K | F254: 17 | G254: DEN | H254: =(IF(I254="",Legend!$B$32,I254)*Legend!$B$23+IF(J254="",Legend!$B$33,J254)*Legend!$B$24+IF(K254="",Legend!$B$34,K254)*Legend!$B$25)/(Legend!$B$23+Legend!$B$24+Legend!$B$25) | I254: 174 | J254: 280 | K254: 272 | L254: =IF(COUNT(I254:K254)<2,"",MAX(I254:K254)-MIN(I254:K254))
A255: 251 | B255: 47 | C255: 25 | D255: Troy Franklin | E255: WR | F255: 90 | G255: DEN | H255: =(IF(I255="",Legend!$B$32,I255)*Legend!$B$23+IF(J255="",Legend!$B$33,J255)*Legend!$B$24+IF(K255="",Legend!$B$34,K255)*Legend!$B$25)/(Legend!$B$23+Legend!$B$24+Legend!$B$25) | J255: 260 | K255: 216 | L255: =IF(COUNT(I255:K255)<2,"",MAX(I255:K255)-MIN(I255:K255))
A256: 252 | B256: 47 | C256: 25 | D256: Antonio Williams | E256: WR | F256: 91 | G256: WAS | H256: =(IF(I256="",Legend!$B$32,I256)*Legend!$B$23+IF(J256="",Legend!$B$33,J256)*Legend!$B$24+IF(K256="",Legend!$B$34,K256)*Legend!$B$25)/(Legend!$B$23+Legend!$B$24+Legend!$B$25) | I256: 299 | J256: 243 | K256: 235 | L256: =IF(COUNT(I256:K256)<2,"",MAX(I256:K256)-MIN(I256:K256))
A257: 253 | B257: 47 | C257: 5 | D257: Cleveland Browns | E257: DST | F257: 16 | G257: CLE | H257: =(IF(I257="",Legend!$B$32,I257)*Legend!$B$23+IF(J257="",Legend!$B$33,J257)*Legend!$B$24+IF(K257="",Legend!$B$34,K257)*Legend!$B$25)/(Legend!$B$23+Legend!$B$24+Legend!$B$25) | I257: 239 | J257: 302 | K257: 236 | L257: =IF(COUNT(I257:K257)<2,"",MAX(I257:K257)-MIN(I257:K257))
A258: 254 | B258: 47 | C258: 25 | D258: Darnell Mooney | E258: WR | F258: 92 | G258: NYG | H258: =(IF(I258="",Legend!$B$32,I258)*Legend!$B$23+IF(J258="",Legend!$B$33,J258)*Legend!$B$24+IF(K258="",Legend!$B$34,K258)*Legend!$B$25)/(Legend!$B$23+Legend!$B$24+Legend!$B$25) | J258: 265 | K258: 217 | L258: =IF(COUNT(I258:K258)<2,"",MAX(I258:K258)-MIN(I258:K258))
A259: 255 | B259: 47 | C259: 15 | D259: David Njoku | E259: TE | F259: 32 | G259: LAC | H259: =(IF(I259="",Legend!$B$32,I259)*Legend!$B$23+IF(J259="",Legend!$B$33,J259)*Legend!$B$24+IF(K259="",Legend!$B$34,K259)*Legend!$B$25)/(Legend!$B$23+Legend!$B$24+Legend!$B$25) | I259: 282 | J259: 254 | K259: 241 | L259: =IF(COUNT(I259:K259)<2,"",MAX(I259:K259)-MIN(I259:K259))
A260: 256 | B260: 47 | C260: 20 | D260: Ollie Gordon II | E260: RB | F260: 69 | G260: MIA | H260: =(IF(I260="",Legend!$B$32,I260)*Legend!$B$23+IF(J260="",Legend!$B$33,J260)*Legend!$B$24+IF(K260="",Legend!$B$34,K260)*Legend!$B$25)/(Legend!$B$23+Legend!$B$24+Legend!$B$25) | I260: 301 | J260: 230 | K260: 244 | L260: =IF(COUNT(I260:K260)<2,"",MAX(I260:K260)-MIN(I260:K260))
A261: 257 | B261: 47 | C261: 20 | D261: Samaje Perine | E261: RB | F261: 70 | G261: CIN | H261: =(IF(I261="",Legend!$B$32,I261)*Legend!$B$23+IF(J261="",Legend!$B$33,J261)*Legend!$B$24+IF(K261="",Legend!$B$34,K261)*Legend!$B$25)/(Legend!$B$23+Legend!$B$24+Legend!$B$25) | I261: 199 | J261: 282 | K261: 269 | L261: =IF(COUNT(I261:K261)<2,"",MAX(I261:K261)-MIN(I261:K261))
A262: 258 | B262: 47 | C262: 25 | D262: Ted Hurst III | E262: WR | F262: 93 | G262: TB | H262: =(IF(I262="",Legend!$B$32,I262)*Legend!$B$23+IF(J262="",Legend!$B$33,J262)*Legend!$B$24+IF(K262="",Legend!$B$34,K262)*Legend!$B$25)/(Legend!$B$23+Legend!$B$24+Legend!$B$25) | I262: 294 | J262: 222 | K262: 254 | L262: =IF(COUNT(I262:K262)<2,"",MAX(I262:K262)-MIN(I262:K262))
A263: 259 | B263: 47 | C263: 19 | D263: Tua Tagovailoa | E263: QB | F263: 31 | G263: ATL | H263: =(IF(I263="",Legend!$B$32,I263)*Legend!$B$23+IF(J263="",Legend!$B$33,J263)*Legend!$B$24+IF(K263="",Legend!$B$34,K263)*Legend!$B$25)/(Legend!$B$23+Legend!$B$24+Legend!$B$25) | I263: 261 | J263: 253 | K263: 258 | L263: =IF(COUNT(I263:K263)<2,"",MAX(I263:K263)-MIN(I263:K263))
A264: 260 | B264: 48 | C264: 21 | D264: Isaiah Davis | E264: RB | F264: 71 | G264: NYJ | H264: =(IF(I264="",Legend!$B$32,I264)*Legend!$B$23+IF(J264="",Legend!$B$33,J264)*Legend!$B$24+IF(K264="",Legend!$B$34,K264)*Legend!$B$25)/(Legend!$B$23+Legend!$B$24+Legend!$B$25) | I264: 293 | J264: 236 | K264: 256 | L264: =IF(COUNT(I264:K264)<2,"",MAX(I264:K264)-MIN(I264:K264))
A265: 261 | B265: 48 | C265: 5 | D265: San Francisco 49ers | E265: DST | F265: 17 | G265: SF | H265: =(IF(I265="",Legend!$B$32,I265)*Legend!$B$23+IF(J265="",Legend!$B$33,J265)*Legend!$B$24+IF(K265="",Legend!$B$34,K265)*Legend!$B$25)/(Legend!$B$23+Legend!$B$24+Legend!$B$25) | I265: 234 | J265: 247 | K265: 280 | L265: =IF(COUNT(I265:K265)<2,"",MAX(I265:K265)-MIN(I265:K265))
A266: 262 | B266: 48 | C266: 21 | D266: George Holani | E266: RB | F266: 72 | G266: SEA | H266: =(IF(I266="",Legend!$B$32,I266)*Legend!$B$23+IF(J266="",Legend!$B$33,J266)*Legend!$B$24+IF(K266="",Legend!$B$34,K266)*Legend!$B$25)/(Legend!$B$23+Legend!$B$24+Legend!$B$25) | I266: 276 | J266: 286 | K266: 243 | L266: =IF(COUNT(I266:K266)<2,"",MAX(I266:K266)-MIN(I266:K266))
...
